...
----------------------------------------------------------------------
Ran 3 tests in 0.701s

OK
...
----------------------------------------------------------------------
Ran 3 tests in 1.044s

OK
...
----------------------------------------------------------------------
Ran 3 tests in 1.093s

OK
...
----------------------------------------------------------------------
Ran 3 tests in 0.946s

OK
F..
======================================================================
FAIL: test_add_user (__main__.Test)
----------------------------------------------------------------------
Traceback (most recent call last):
  File ".\unit_test.py", line 37, in test_add_user
    self.assertEqual(UserController.add_user(self.user_1), 'SuccesS')
AssertionError: 'Success' != 'SuccesS'
- Success
?       ^
+ SuccesS
?       ^


----------------------------------------------------------------------
Ran 3 tests in 0.824s

FAILED (failures=1)
